.class public final Lio/netty/util/internal/PromiseNotificationUtil;
.super Ljava/lang/Object;
.source "SourceFile"


# direct methods
.method private constructor <init>()V
    .locals 0

    .line 1
    invoke-direct {p0}, Ljava/lang/Object;-><init>()V

    .line 2
    .line 3
    .line 4
    return-void
.end method

.method public static tryCancel(Lio/netty/util/concurrent/Promise;Lio/netty/util/internal/logging/InternalLogger;)V
    .locals 2
    .annotation system Ldalvik/annotation/Signature;
        value = {
            "(",
            "Lio/netty/util/concurrent/Promise<",
            "*>;",
            "Lio/netty/util/internal/logging/InternalLogger;",
            ")V"
        }
    .end annotation

    .line 1
    const/4 v0, 0x0

    .line 2
    invoke-interface {p0, v0}, Lio/netty/util/concurrent/Future;->cancel(Z)Z

    .line 3
    .line 4
    .line 5
    move-result v0

    .line 6
    if-nez v0, :cond_1

    .line 7
    .line 8
    if-eqz p1, :cond_1

    .line 9
    .line 10
    invoke-interface {p0}, Lio/netty/util/concurrent/Future;->cause()Ljava/lang/Throwable;

    .line 11
    .line 12
    .line 13
    move-result-object v0

    .line 14
    if-nez v0, :cond_0

    .line 15
    .line 16
    const-string v0, "Failed to cancel promise because it has succeeded already: {}"

    .line 17
    .line 18
    invoke-interface {p1, v0, p0}, Lio/netty/util/internal/logging/InternalLogger;->warn(Ljava/lang/String;Ljava/lang/Object;)V

    .line 19
    .line 20
    .line 21
    goto :goto_0

    .line 22
    :cond_0
    const-string v1, "Failed to cancel promise because it has failed already: {}, unnotified cause:"

    .line 23
    .line 24
    invoke-interface {p1, v1, p0, v0}, Lio/netty/util/internal/logging/InternalLogger;->warn(Ljava/lang/String;Ljava/lang/Object;Ljava/lang/Object;)V

    .line 25
    .line 26
    .line 27
    :cond_1
    :goto_0
    return-void
.end method

.method public static tryFailure(Lio/netty/util/concurrent/Promise;Ljava/lang/Throwable;Lio/netty/util/internal/logging/InternalLogger;)V
    .locals 2
    .annotation system Ldalvik/annotation/Signature;
        value = {
            "(",
            "Lio/netty/util/concurrent/Promise<",
            "*>;",
            "Ljava/lang/Throwable;",
            "Lio/netty/util/internal/logging/InternalLogger;",
            ")V"
        }
    .end annotation

    .line 1
    invoke-interface {p0, p1}, Lio/netty/util/concurrent/Promise;->tryFailure(Ljava/lang/Throwable;)Z

    .line 2
    .line 3
    .line 4
    move-result v0

    .line 5
    if-nez v0, :cond_1

    .line 6
    .line 7
    if-eqz p2, :cond_1

    .line 8
    .line 9
    invoke-interface {p0}, Lio/netty/util/concurrent/Future;->cause()Ljava/lang/Throwable;

    .line 10
    .line 11
    .line 12
    move-result-object v0

    .line 13
    if-nez v0, :cond_0

    .line 14
    .line 15
    const-string v0, "Failed to mark a promise as failure because it has succeeded already: {}"

    .line 16
    .line 17
    invoke-interface {p2, v0, p0, p1}, Lio/netty/util/internal/logging/InternalLogger;->warn(Ljava/lang/String;Ljava/lang/Object;Ljava/lang/Object;)V

    .line 18
    .line 19
    .line 20
    goto :goto_0

    .line 21
    :cond_0
    invoke-interface {p2}, Lio/netty/util/internal/logging/InternalLogger;->isWarnEnabled()Z

    .line 22
    .line 23
    .line 24
    move-result v1

    .line 25
    if-eqz v1, :cond_1

    .line 26
    .line 27
    invoke-static {v0}, Lio/netty/util/internal/ThrowableUtil;->stackTraceToString(Ljava/lang/Throwable;)Ljava/lang/String;

    .line 28
    .line 29
    .line 30
    move-result-object v0

    .line 31
    filled-new-array {p0, v0, p1}, [Ljava/lang/Object;

    .line 32
    .line 33
    .line 34
    move-result-object p0

    .line 35
    const-string p1, "Failed to mark a promise as failure because it has failed already: {}, unnotified cause: {}"

    .line 36
    .line 37
    invoke-interface {p2, p1, p0}, Lio/netty/util/internal/logging/InternalLogger;->warn(Ljava/lang/String;[Ljava/lang/Object;)V

    .line 38
    .line 39
    .line 40
    :cond_1
    :goto_0
    return-void
.end method

.method public static trySuccess(Lio/netty/util/concurrent/Promise;Ljava/lang/Object;Lio/netty/util/internal/logging/InternalLogger;)V
    .locals 1
    .annotation system Ldalvik/annotation/Signature;
        value = {
            "<V:",
            "Ljava/lang/Object;",
            ">(",
            "Lio/netty/util/concurrent/Promise<",
            "-TV;>;TV;",
            "Lio/netty/util/internal/logging/InternalLogger;",
            ")V"
        }
    .end annotation

    .line 1
    invoke-interface {p0, p1}, Lio/netty/util/concurrent/Promise;->trySuccess(Ljava/lang/Object;)Z

    .line 2
    .line 3
    .line 4
    move-result p1

    .line 5
    if-nez p1, :cond_1

    .line 6
    .line 7
    if-eqz p2, :cond_1

    .line 8
    .line 9
    invoke-interface {p0}, Lio/netty/util/concurrent/Future;->cause()Ljava/lang/Throwable;

    .line 10
    .line 11
    .line 12
    move-result-object p1

    .line 13
    if-nez p1, :cond_0

    .line 14
    .line 15
    const-string p1, "Failed to mark a promise as success because it has succeeded already: {}"

    .line 16
    .line 17
    invoke-interface {p2, p1, p0}, Lio/netty/util/internal/logging/InternalLogger;->warn(Ljava/lang/String;Ljava/lang/Object;)V

    .line 18
    .line 19
    .line 20
    goto :goto_0

    .line 21
    :cond_0
    const-string v0, "Failed to mark a promise as success because it has failed already: {}, unnotified cause:"

    .line 22
    .line 23
    invoke-interface {p2, v0, p0, p1}, Lio/netty/util/internal/logging/InternalLogger;->warn(Ljava/lang/String;Ljava/lang/Object;Ljava/lang/Object;)V

    .line 24
    .line 25
    .line 26
    :cond_1
    :goto_0
    return-void
.end method
